Workbook

Sheet Assumptions
A1: OX Financial Model - Assumptions
A2: Date | B2: 2026-06-10
A3: Category | B3: Metric | C3: Conservative | D3: Base | E3: Upside | F3: Unit / type | G3: Source / note
A4: Product economy | B4: Prize pool share | C4: 0.8 | D4: 0.8 | E4: 0.8 | F4: % of valid GMV | G4: Internal OX TZ: prize pool and jackpot
A5: Product economy | B5: Platform fee share | C5: 0.1 | D5: 0.1 | E5: 0.1 | F5: % of valid GMV | G5: Internal OX TZ: platform fee
A6: Product economy | B6: Jackpot contribution share | C6: 0.1 | D6: 0.1 | E6: 0.1 | F6: % of valid GMV | G6: Internal OX TZ: next jackpot contribution
A7: Product economy | B7: Gas reserve share of platform fee | C7: 0.2 | D7: 0.2 | E7: 0.2 | F7: % of platform fee | G7: Internal OX TZ: MVP gas reserve
A8: Product economy | B8: Net platform margin before OPEX | C8: 0.08 | D8: 0.08 | E8: 0.08 | F8: % of valid GMV | G8: Platform fee minus gas reserve
A9: Product economy | B9: Minimum public jackpot | C9: 5000 | D9: 5000 | E9: 5000 | F9: USDC | G9: Internal OX TZ: MVP minimum jackpot
A10: Funnel | B10: Starting monthly visits | C10: 10000 | D10: 30000 | E10: 80000 | F10: visits | G10: Hypothesis: first live country/month
A11: Funnel | B11: Monthly visit growth | C11: 0.1 | D11: 0.18 | E11: 0.28 | F11: % m/m | G11: Scenario assumption
A12: Funnel | B12: Eligible user rate after geo/compliance | C12: 0.75 | D12: 0.82 | E12: 0.88 | F12: % of visits | G12: After blocked country/VPN/proxy/compliance filters
A13: Funnel | B13: Wallet connect rate | C13: 0.12 | D13: 0.18 | E13: 0.25 | F13: % of eligible users | G13: UX/onboarding assumption
A14: Funnel | B14: USDC readiness rate | C14: 0.55 | D14: 0.65 | E14: 0.75 | F14: % of connected wallets | G14: User can buy with USDC
A15: Funnel | B15: First purchase conversion | C15: 0.25 | D15: 0.32 | E15: 0.4 | F15: % of USDC-ready users | G15: Ticket purchase conversion
... A33: Funding | B33: Initial cash buffer | C33: 100000 | D33: 150000 | E33: 250000 | F33: USDC | G33: Operational contingency

Sheet Country Rollout
A1: Queue | B1: Country / region | C1: Localization | D1: Launch status | E1: Main launch gates | F1: Digital / market signal | G1: Crypto / payment signal | H1: Primary GTM channels | I1: Source / note
A2: 1 | B2: Nigeria | C2: English first | D2: Candidate for first legal analysis | E2: Federal/state betting or lottery classification; crypto payments; AML; advertising; taxes | F2: DataReportal 2025: 107M internet users, 150M mobile connections | G2: Chainalysis 2025: rank 6 global crypto adoption | H2: Football media, Telegram/X, sports influencers, affiliates, crypto communities | I2: https://datareportal.com/reports/digital-2025-nigeria; https://www.chainalysis.com/blog/2025-global-crypto-adoption-index/
A3: 1 | B3: Kenya | C3: English + Swahili | D3: Candidate for first legal analysis | E3: GRA licensing; Gambling Control Act 2025; online gambling; advertising; responsible gaming; crypto payments | F3: DataReportal 2025: 27.4M internet users; mobile connections 121% population | G3: Requires country-specific USDC/payment memo | H3: Sports media, mobile-first partners, football communities, compliant influencers | I3: https://datareportal.com/reports/digital-2025-kenya; https://gra.go.ke/about/
A4: 2 | B4: Ghana | C4: English | D4: Second-wave candidate | E4: Gaming Commission licensing; AML/CFT; advertising; payment rules; crypto treatment | F4: DataReportal 2025: 24.3M internet users; 69.9% penetration | G4: Requires country-specific crypto/payment memo | H4: Football pages, Facebook/YouTube, sports media, affiliates | I4: https://datareportal.com/reports/digital-2025-ghana; https://www.gamingcommission.gov.gh/
A5: 2 | B5: Tanzania | C5: Swahili + English support | D5: Second-wave candidate | E5: Gaming Board licensing; online gaming; payment/KYC; advertising | F5: DataReportal 2025: 79M mobile connections; 20.2M internet users | G5: Requires country-specific crypto/payment memo | H5: Swahili sports communities, local affiliates, football media | I5: https://datareportal.com/reports/digital-2025-tanzania; https://www.gamingboard.go.tz/
A6: 2 | B6: Uganda | C6: English | D6: Second-wave candidate | E6: NLGRB licensing; responsible gaming; advertising; payment/KYC | F6: DataReportal 2025: 38.6M mobile connections; 14.2M internet users | G6: Requires country-specific crypto/payment memo | H6: Sports communities, regional affiliates, responsible gaming campaigns | I6: https://datareportal.com/reports/digital-2025-uganda; https://lgrb.go.ug/
A7: 2 | B7: Zambia | C7: English | D7: Second-wave candidate | E7: Betting licensing; tax; advertising; crypto payments; AML | F7: DataReportal 2025: 19.9M mobile connections; 7.13M internet users | G7: Requires country-specific crypto/payment memo | H7: Focused partner tests, sports media, low-budget cohorts | I7: https://datareportal.com/reports/digital-2025-zambia
A8: 3 / watchlist | B8: Brazil | C8: Portuguese | D8: Watchlist only | E8: Local authorization; .bet.br; local entity; consumer protection; likely crypto-payment restrictions | F8: Large football/digital market | G8: Chainalysis 2025: rank 5; payment legality must be confirmed | H8: Only after local counsel and payment route | I8: https://www.gov.br/fazenda/pt-br/composicao/orgaos/secretaria-de-premios-e-apostas
A9: 3 / watchlist | B9: Kazakhstan | C9: Russian/Kazakh | D9: Watchlist only | E9: License; payments; server/data requirements; crypto treatment; sanctions/AML | F9: Commercially relevant regional audience | G9: Requires legal/payment memo | H9: Only after local legal clearance | I9: Internal TZ watchlist
A10: 3 / watchlist | B10: Uzbekistan | C10: Uzbek/Russian | D10: Watchlist only | E10: Gambling/payment/ads/KYC uncertainty | F10: Potential Central Asia market | G10: Requires legal/payment memo | H10: Only after explicit legal route | I10: Internal TZ watchlist
A11: 3 / watchlist | B11: South Africa | C11: English | D11: Watchlist only | E11: Provincial betting license; online restrictions; crypto payment uncertainty | F11: Commercially attractive but complex | G11: Requires payment and license memo | H11: Only with local licensing route | I11: Internal TZ watchlist
A12: 3 / watchlist | B12: Vietnam | C12: Vietnamese | D12: Watchlist only | E12: Gambling restrictions for residents; advertising; payments | F12: High digital/crypto interest but high legal risk | G12: Requires explicit legal route | H12: Do not target before legal clearance | I12: Internal TZ watchlist
... A14: Red zone | B14: US, Canada, UK, EU/EEA, Australia, India, Indonesia, China, Russia/Belarus, Turkey, Gulf restricted markets, sanctions territories | C14: N/A | D14: Blocked for MVP | E14: No targeting or purchase permit without separate license/approval | F14: High regulatory/sanctions/advertising risk | G14: Not eligible for MVP | H14: No marketing | I14: Internal TZ red zone

Sheet Funnel
A1: Month | B1: Scenario | C1: Countries active | D1: Visits | E1: Eligible users | F1: Wallet connected | G1: USDC ready | H1: First buyers | I1: Repeat buyers | J1: Active paying users
A2: 1 | B2: Conservative | C2: =IF(A2<7,1,IF(A2<13,2,IF(A2<24,3,4))) | D2: =INDEX(Assumptions!$C:$E,MATCH("Starting monthly visits",Assumptions!$B:$B,0),MATCH(B2,Assumptions!$C$3:$E$3,0))*POWER(1+INDEX(Assumptions!$C:$E,MATCH("Monthly visit growth",Assumptions!$B:$B,0),MATCH(B2,Assumptions!$C$3:$E$3,0)),A2-1)*C2 | E2: =D2*INDEX(Assumptions!$C:$E,MATCH("Eligible user rate after geo/compliance",Assumptions!$B:$B,0),MATCH(B2,Assumptions!$C$3:$E$3,0)) | F2: =E2*INDEX(Assumptions!$C:$E,MATCH("Wallet connect rate",Assumptions!$B:$B,0),MATCH(B2,Assumptions!$C$3:$E$3,0)) | G2: =F2*INDEX(Assumptions!$C:$E,MATCH("USDC readiness rate",Assumptions!$B:$B,0),MATCH(B2,Assumptions!$C$3:$E$3,0)) | H2: =G2*INDEX(Assumptions!$C:$E,MATCH("First purchase conversion",Assumptions!$B:$B,0),MATCH(B2,Assumptions!$C$3:$E$3,0)) | I2: =0*INDEX(Assumptions!$C:$E,MATCH("Repeat purchase rate",Assumptions!$B:$B,0),MATCH(B2,Assumptions!$C$3:$E$3,0)) | J2: =H2+I2
A3: 2 | B3: Conservative | C3: =IF(A3<7,1,IF(A3<13,2,IF(A3<24,3,4))) | D3: =INDEX(Assumptions!$C:$E,MATCH("Starting monthly visits",Assumptions!$B:$B,0),MATCH(B3,Assumptions!$C$3:$E$3,0))*POWER(1+INDEX(Assumptions!$C:$E,MATCH("Monthly visit growth",Assumptions!$B:$B,0),MATCH(B3,Assumptions!$C$3:$E$3,0)),A3-1)*C3 | E3: =D3*INDEX(Assumptions!$C:$E,MATCH("Eligible user rate after geo/compliance",Assumptions!$B:$B,0),MATCH(B3,Assumptions!$C$3:$E$3,0)) | F3: =E3*INDEX(Assumptions!$C:$E,MATCH("Wallet connect rate",Assumptions!$B:$B,0),MATCH(B3,Assumptions!$C$3:$E$3,0)) | G3: =F3*INDEX(Assumptions!$C:$E,MATCH("USDC readiness rate",Assumptions!$B:$B,0),MATCH(B3,Assumptions!$C$3:$E$3,0)) | H3: =G3*INDEX(Assumptions!$C:$E,MATCH("First purchase conversion",Assumptions!$B:$B,0),MATCH(B3,Assumptions!$C$3:$E$3,0)) | I3: =J2*INDEX(Assumptions!$C:$E,MATCH("Repeat purchase rate",Assumptions!$B:$B,0),MATCH(B3,Assumptions!$C$3:$E$3,0)) | J3: =H3+I3
A4: 3 | B4: Conservative | C4: =IF(A4<7,1,IF(A4<13,2,IF(A4<24,3,4))) | D4: =INDEX(Assumptions!$C:$E,MATCH("Starting monthly visits",Assumptions!$B:$B,0),MATCH(B4,Assumptions!$C$3:$E$3,0))*POWER(1+INDEX(Assumptions!$C:$E,MATCH("Monthly visit growth",Assumptions!$B:$B,0),MATCH(B4,Assumptions!$C$3:$E$3,0)),A4-1)*C4 | E4: =D4*INDEX(Assumptions!$C:$E,MATCH("Eligible user rate after geo/compliance",Assumptions!$B:$B,0),MATCH(B4,Assumptions!$C$3:$E$3,0)) | F4: =E4*INDEX(Assumptions!$C:$E,MATCH("Wallet connect rate",Assumptions!$B:$B,0),MATCH(B4,Assumptions!$C$3:$E$3,0)) | G4: =F4*INDEX(Assumptions!$C:$E,MATCH("USDC readiness rate",Assumptions!$B:$B,0),MATCH(B4,Assumptions!$C$3:$E$3,0)) | H4: =G4*INDEX(Assumptions!$C:$E,MATCH("First purchase conversion",Assumptions!$B:$B,0),MATCH(B4,Assumptions!$C$3:$E$3,0)) | I4: =J3*INDEX(Assumptions!$C:$E,MATCH("Repeat purchase rate",Assumptions!$B:$B,0),MATCH(B4,Assumptions!$C$3:$E$3,0)) | J4: =H4+I4
A5: 4 | B5: Conservative | C5: =IF(A5<7,1,IF(A5<13,2,IF(A5<24,3,4))) | D5: =INDEX(Assumptions!$C:$E,MATCH("Starting monthly visits",Assumptions!$B:$B,0),MATCH(B5,Assumptions!$C$3:$E$3,0))*POWER(1+INDEX(Assumptions!$C:$E,MATCH("Monthly visit growth",Assumptions!$B:$B,0),MATCH(B5,Assumptions!$C$3:$E$3,0)),A5-1)*C5 | E5: =D5*INDEX(Assumptions!$C:$E,MATCH("Eligible user rate after geo/compliance",Assumptions!$B:$B,0),MATCH(B5,Assumptions!$C$3:$E$3,0)) | F5: =E5*INDEX(Assumptions!$C:$E,MATCH("Wallet connect rate",Assumptions!$B:$B,0),MATCH(B5,Assumptions!$C$3:$E$3,0)) | G5: =F5*INDEX(Assumptions!$C:$E,MATCH("USDC readiness rate",Assumptions!$B:$B,0),MATCH(B5,Assumptions!$C$3:$E$3,0)) | H5: =G5*INDEX(Assumptions!$C:$E,MATCH("First purchase conversion",Assumptions!$B:$B,0),MATCH(B5,Assumptions!$C$3:$E$3,0)) | I5: =J4*INDEX(Assumptions!$C:$E,MATCH("Repeat purchase rate",Assumptions!$B:$B,0),MATCH(B5,Assumptions!$C$3:$E$3,0)) | J5: =H5+I5
A6: 5 | B6: Conservative | C6: =IF(A6<7,1,IF(A6<13,2,IF(A6<24,3,4))) | D6: =INDEX(Assumptions!$C:$E,MATCH("Starting monthly visits",Assumptions!$B:$B,0),MATCH(B6,Assumptions!$C$3:$E$3,0))*POWER(1+INDEX(Assumptions!$C:$E,MATCH("Monthly visit growth",Assumptions!$B:$B,0),MATCH(B6,Assumptions!$C$3:$E$3,0)),A6-1)*C6 | E6: =D6*INDEX(Assumptions!$C:$E,MATCH("Eligible user rate after geo/compliance",Assumptions!$B:$B,0),MATCH(B6,Assumptions!$C$3:$E$3,0)) | F6: =E6*INDEX(Assumptions!$C:$E,MATCH("Wallet connect rate",Assumptions!$B:$B,0),MATCH(B6,Assumptions!$C$3:$E$3,0)) | G6: =F6*INDEX(Assumptions!$C:$E,MATCH("USDC readiness rate",Assumptions!$B:$B,0),MATCH(B6,Assumptions!$C$3:$E$3,0)) | H6: =G6*INDEX(Assumptions!$C:$E,MATCH("First purchase conversion",Assumptions!$B:$B,0),MATCH(B6,Assumptions!$C$3:$E$3,0)) | I6: =J5*INDEX(Assumptions!$C:$E,MATCH("Repeat purchase rate",Assumptions!$B:$B,0),MATCH(B6,Assumptions!$C$3:$E$3,0)) | J6: =H6+I6
A7: 6 | B7: Conservative | C7: =IF(A7<7,1,IF(A7<13,2,IF(A7<24,3,4))) | D7: =INDEX(Assumptions!$C:$E,MATCH("Starting monthly visits",Assumptions!$B:$B,0),MATCH(B7,Assumptions!$C$3:$E$3,0))*POWER(1+INDEX(Assumptions!$C:$E,MATCH("Monthly visit growth",Assumptions!$B:$B,0),MATCH(B7,Assumptions!$C$3:$E$3,0)),A7-1)*C7 | E7: =D7*INDEX(Assumptions!$C:$E,MATCH("Eligible user rate after geo/compliance",Assumptions!$B:$B,0),MATCH(B7,Assumptions!$C$3:$E$3,0)) | F7: =E7*INDEX(Assumptions!$C:$E,MATCH("Wallet connect rate",Assumptions!$B:$B,0),MATCH(B7,Assumptions!$C$3:$E$3,0)) | G7: =F7*INDEX(Assumptions!$C:$E,MATCH("USDC readiness rate",Assumptions!$B:$B,0),MATCH(B7,Assumptions!$C$3:$E$3,0)) | H7: =G7*INDEX(Assumptions!$C:$E,MATCH("First purchase conversion",Assumptions!$B:$B,0),MATCH(B7,Assumptions!$C$3:$E$3,0)) | I7: =J6*INDEX(Assumptions!$C:$E,MATCH("Repeat purchase rate",Assumptions!$B:$B,0),MATCH(B7,Assumptions!$C$3:$E$3,0)) | J7: =H7+I7
A8: 7 | B8: Conservative | C8: =IF(A8<7,1,IF(A8<13,2,IF(A8<24,3,4))) | D8: =INDEX(Assumptions!$C:$E,MATCH("Starting monthly visits",Assumptions!$B:$B,0),MATCH(B8,Assumptions!$C$3:$E$3,0))*POWER(1+INDEX(Assumptions!$C:$E,MATCH("Monthly visit growth",Assumptions!$B:$B,0),MATCH(B8,Assumptions!$C$3:$E$3,0)),A8-1)*C8 | E8: =D8*INDEX(Assumptions!$C:$E,MATCH("Eligible user rate after geo/compliance",Assumptions!$B:$B,0),MATCH(B8,Assumptions!$C$3:$E$3,0)) | F8: =E8*INDEX(Assumptions!$C:$E,MATCH("Wallet connect rate",Assumptions!$B:$B,0),MATCH(B8,Assumptions!$C$3:$E$3,0)) | G8: =F8*INDEX(Assumptions!$C:$E,MATCH("USDC readiness rate",Assumptions!$B:$B,0),MATCH(B8,Assumptions!$C$3:$E$3,0)) | H8: =G8*INDEX(Assumptions!$C:$E,MATCH("First purchase conversion",Assumptions!$B:$B,0),MATCH(B8,Assumptions!$C$3:$E$3,0)) | I8: =J7*INDEX(Assumptions!$C:$E,MATCH("Repeat purchase rate",Assumptions!$B:$B,0),MATCH(B8,Assumptions!$C$3:$E$3,0)) | J8: =H8+I8
A9: 8 | B9: Conservative | C9: =IF(A9<7,1,IF(A9<13,2,IF(A9<24,3,4))) | D9: =INDEX(Assumptions!$C:$E,MATCH("Starting monthly visits",Assumptions!$B:$B,0),MATCH(B9,Assumptions!$C$3:$E$3,0))*POWER(1+INDEX(Assumptions!$C:$E,MATCH("Monthly visit growth",Assumptions!$B:$B,0),MATCH(B9,Assumptions!$C$3:$E$3,0)),A9-1)*C9 | E9: =D9*INDEX(Assumptions!$C:$E,MATCH("Eligible user rate after geo/compliance",Assumptions!$B:$B,0),MATCH(B9,Assumptions!$C$3:$E$3,0)) | F9: =E9*INDEX(Assumptions!$C:$E,MATCH("Wallet connect rate",Assumptions!$B:$B,0),MATCH(B9,Assumptions!$C$3:$E$3,0)) | G9: =F9*INDEX(Assumptions!$C:$E,MATCH("USDC readiness rate",Assumptions!$B:$B,0),MATCH(B9,Assumptions!$C$3:$E$3,0)) | H9: =G9*INDEX(Assumptions!$C:$E,MATCH("First purchase conversion",Assumptions!$B:$B,0),MATCH(B9,Assumptions!$C$3:$E$3,0)) | I9: =J8*INDEX(Assumptions!$C:$E,MATCH("Repeat purchase rate",Assumptions!$B:$B,0),MATCH(B9,Assumptions!$C$3:$E$3,0)) | J9: =H9+I9
A10: 9 | B10: Conservative | C10: =IF(A10<7,1,IF(A10<13,2,IF(A10<24,3,4))) | D10: =INDEX(Assumptions!$C:$E,MATCH("Starting monthly visits",Assumptions!$B:$B,0),MATCH(B10,Assumptions!$C$3:$E$3,0))*POWER(1+INDEX(Assumptions!$C:$E,MATCH("Monthly visit growth",Assumptions!$B:$B,0),MATCH(B10,Assumptions!$C$3:$E$3,0)),A10-1)*C10 | E10: =D10*INDEX(Assumptions!$C:$E,MATCH("Eligible user rate after geo/compliance",Assumptions!$B:$B,0),MATCH(B10,Assumptions!$C$3:$E$3,0)) | F10: =E10*INDEX(Assumptions!$C:$E,MATCH("Wallet connect rate",Assumptions!$B:$B,0),MATCH(B10,Assumptions!$C$3:$E$3,0)) | G10: =F10*INDEX(Assumptions!$C:$E,MATCH("USDC readiness rate",Assumptions!$B:$B,0),MATCH(B10,Assumptions!$C$3:$E$3,0)) | H10: =G10*INDEX(Assumptions!$C:$E,MATCH("First purchase conversion",Assumptions!$B:$B,0),MATCH(B10,Assumptions!$C$3:$E$3,0)) | I10: =J9*INDEX(Assumptions!$C:$E,MATCH("Repeat purchase rate",Assumptions!$B:$B,0),MATCH(B10,Assumptions!$C$3:$E$3,0)) | J10: =H10+I10
A11: 10 | B11: Conservative | C11: =IF(A11<7,1,IF(A11<13,2,IF(A11<24,3,4))) | D11: =INDEX(Assumptions!$C:$E,MATCH("Starting monthly visits",Assumptions!$B:$B,0),MATCH(B11,Assumptions!$C$3:$E$3,0))*POWER(1+INDEX(Assumptions!$C:$E,MATCH("Monthly visit growth",Assumptions!$B:$B,0),MATCH(B11,Assumptions!$C$3:$E$3,0)),A11-1)*C11 | E11: =D11*INDEX(Assumptions!$C:$E,MATCH("Eligible user rate after geo/compliance",Assumptions!$B:$B,0),MATCH(B11,Assumptions!$C$3:$E$3,0)) | F11: =E11*INDEX(Assumptions!$C:$E,MATCH("Wallet connect rate",Assumptions!$B:$B,0),MATCH(B11,Assumptions!$C$3:$E$3,0)) | G11: =F11*INDEX(Assumptions!$C:$E,MATCH("USDC readiness rate",Assumptions!$B:$B,0),MATCH(B11,Assumptions!$C$3:$E$3,0)) | H11: =G11*INDEX(Assumptions!$C:$E,MATCH("First purchase conversion",Assumptions!$B:$B,0),MATCH(B11,Assumptions!$C$3:$E$3,0)) | I11: =J10*INDEX(Assumptions!$C:$E,MATCH("Repeat purchase rate",Assumptions!$B:$B,0),MATCH(B11,Assumptions!$C$3:$E$3,0)) | J11: =H11+I11
A12: 11 | B12: Conservative | C12: =IF(A12<7,1,IF(A12<13,2,IF(A12<24,3,4))) | D12: =INDEX(Assumptions!$C:$E,MATCH("Starting monthly visits",Assumptions!$B:$B,0),MATCH(B12,Assumptions!$C$3:$E$3,0))*POWER(1+INDEX(Assumptions!$C:$E,MATCH("Monthly visit growth",Assumptions!$B:$B,0),MATCH(B12,Assumptions!$C$3:$E$3,0)),A12-1)*C12 | E12: =D12*INDEX(Assumptions!$C:$E,MATCH("Eligible user rate after geo/compliance",Assumptions!$B:$B,0),MATCH(B12,Assumptions!$C$3:$E$3,0)) | F12: =E12*INDEX(Assumptions!$C:$E,MATCH("Wallet connect rate",Assumptions!$B:$B,0),MATCH(B12,Assumptions!$C$3:$E$3,0)) | G12: =F12*INDEX(Assumptions!$C:$E,MATCH("USDC readiness rate",Assumptions!$B:$B,0),MATCH(B12,Assumptions!$C$3:$E$3,0)) | H12: =G12*INDEX(Assumptions!$C:$E,MATCH("First purchase conversion",Assumptions!$B:$B,0),MATCH(B12,Assumptions!$C$3:$E$3,0)) | I12: =J11*INDEX(Assumptions!$C:$E,MATCH("Repeat purchase rate",Assumptions!$B:$B,0),MATCH(B12,Assumptions!$C$3:$E$3,0)) | J12: =H12+I12
A13: 12 | B13: Conservative | C13: =IF(A13<7,1,IF(A13<13,2,IF(A13<24,3,4))) | D13: =INDEX(Assumptions!$C:$E,MATCH("Starting monthly visits",Assumptions!$B:$B,0),MATCH(B13,Assumptions!$C$3:$E$3,0))*POWER(1+INDEX(Assumptions!$C:$E,MATCH("Monthly visit growth",Assumptions!$B:$B,0),MATCH(B13,Assumptions!$C$3:$E$3,0)),A13-1)*C13 | E13: =D13*INDEX(Assumptions!$C:$E,MATCH("Eligible user rate after geo/compliance",Assumptions!$B:$B,0),MATCH(B13,Assumptions!$C$3:$E$3,0)) | F13: =E13*INDEX(Assumptions!$C:$E,MATCH("Wallet connect rate",Assumptions!$B:$B,0),MATCH(B13,Assumptions!$C$3:$E$3,0)) | G13: =F13*INDEX(Assumptions!$C:$E,MATCH("USDC readiness rate",Assumptions!$B:$B,0),MATCH(B13,Assumptions!$C$3:$E$3,0)) | H13: =G13*INDEX(Assumptions!$C:$E,MATCH("First purchase conversion",Assumptions!$B:$B,0),MATCH(B13,Assumptions!$C$3:$E$3,0)) | I13: =J12*INDEX(Assumptions!$C:$E,MATCH("Repeat purchase rate",Assumptions!$B:$B,0),MATCH(B13,Assumptions!$C$3:$E$3,0)) | J13: =H13+I13
A14: 13 | B14: Conservative | C14: =IF(A14<7,1,IF(A14<13,2,IF(A14<24,3,4))) | D14: =INDEX(Assumptions!$C:$E,MATCH("Starting monthly visits",Assumptions!$B:$B,0),MATCH(B14,Assumptions!$C$3:$E$3,0))*POWER(1+INDEX(Assumptions!$C:$E,MATCH("Monthly visit growth",Assumptions!$B:$B,0),MATCH(B14,Assumptions!$C$3:$E$3,0)),A14-1)*C14 | E14: =D14*INDEX(Assumptions!$C:$E,MATCH("Eligible user rate after geo/compliance",Assumptions!$B:$B,0),MATCH(B14,Assumptions!$C$3:$E$3,0)) | F14: =E14*INDEX(Assumptions!$C:$E,MATCH("Wallet connect rate",Assumptions!$B:$B,0),MATCH(B14,Assumptions!$C$3:$E$3,0)) | G14: =F14*INDEX(Assumptions!$C:$E,MATCH("USDC readiness rate",Assumptions!$B:$B,0),MATCH(B14,Assumptions!$C$3:$E$3,0)) | H14: =G14*INDEX(Assumptions!$C:$E,MATCH("First purchase conversion",Assumptions!$B:$B,0),MATCH(B14,Assumptions!$C$3:$E$3,0)) | I14: =J13*INDEX(Assumptions!$C:$E,MATCH("Repeat purchase rate",Assumptions!$B:$B,0),MATCH(B14,Assumptions!$C$3:$E$3,0)) | J14: =H14+I14
... A37: 36 | B37: Conservative | C37: =IF(A37<7,1,IF(A37<13,2,IF(A37<24,3,4))) | D37: =INDEX(Assumptions!$C:$E,MATCH("Starting monthly visits",Assumptions!$B:$B,0),MATCH(B37,Assumptions!$C$3:$E$3,0))*POWER(1+INDEX(Assumptions!$C:$E,MATCH("Monthly visit growth",Assumptions!$B:$B,0),MATCH(B37,Assumptions!$C$3:$E$3,0)),A37-1)*C37 | E37: =D37*INDEX(Assumptions!$C:$E,MATCH("Eligible user rate after geo/compliance",Assumptions!$B:$B,0),MATCH(B37,Assumptions!$C$3:$E$3,0)) | F37: =E37*INDEX(Assumptions!$C:$E,MATCH("Wallet connect rate",Assumptions!$B:$B,0),MATCH(B37,Assumptions!$C$3:$E$3,0)) | G37: =F37*INDEX(Assumptions!$C:$E,MATCH("USDC readiness rate",Assumptions!$B:$B,0),MATCH(B37,Assumptions!$C$3:$E$3,0)) | H37: =G37*INDEX(Assumptions!$C:$E,MATCH("First purchase conversion",Assumptions!$B:$B,0),MATCH(B37,Assumptions!$C$3:$E$3,0)) | I37: =J36*INDEX(Assumptions!$C:$E,MATCH("Repeat purchase rate",Assumptions!$B:$B,0),MATCH(B37,Assumptions!$C$3:$E$3,0)) | J37: =H37+I37
A38: 1 | B38: Base | C38: =IF(A38<7,1,IF(A38<13,2,IF(A38<24,3,4))) | D38: =INDEX(Assumptions!$C:$E,MATCH("Starting monthly visits",Assumptions!$B:$B,0),MATCH(B38,Assumptions!$C$3:$E$3,0))*POWER(1+INDEX(Assumptions!$C:$E,MATCH("Monthly visit growth",Assumptions!$B:$B,0),MATCH(B38,Assumptions!$C$3:$E$3,0)),A38-1)*C38 | E38: =D38*INDEX(Assumptions!$C:$E,MATCH("Eligible user rate after geo/compliance",Assumptions!$B:$B,0),MATCH(B38,Assumptions!$C$3:$E$3,0)) | F38: =E38*INDEX(Assumptions!$C:$E,MATCH("Wallet connect rate",Assumptions!$B:$B,0),MATCH(B38,Assumptions!$C$3:$E$3,0)) | G38: =F38*INDEX(Assumptions!$C:$E,MATCH("USDC readiness rate",Assumptions!$B:$B,0),MATCH(B38,Assumptions!$C$3:$E$3,0)) | H38: =G38*INDEX(Assumptions!$C:$E,MATCH("First purchase conversion",Assumptions!$B:$B,0),MATCH(B38,Assumptions!$C$3:$E$3,0)) | I38: =0*INDEX(Assumptions!$C:$E,MATCH("Repeat purchase rate",Assumptions!$B:$B,0),MATCH(B38,Assumptions!$C$3:$E$3,0)) | J38: =H38+I38
A39: 2 | B39: Base | C39: =IF(A39<7,1,IF(A39<13,2,IF(A39<24,3,4))) | D39: =INDEX(Assumptions!$C:$E,MATCH("Starting monthly visits",Assumptions!$B:$B,0),MATCH(B39,Assumptions!$C$3:$E$3,0))*POWER(1+INDEX(Assumptions!$C:$E,MATCH("Monthly visit growth",Assumptions!$B:$B,0),MATCH(B39,Assumptions!$C$3:$E$3,0)),A39-1)*C39 | E39: =D39*INDEX(Assumptions!$C:$E,MATCH("Eligible user rate after geo/compliance",Assumptions!$B:$B,0),MATCH(B39,Assumptions!$C$3:$E$3,0)) | F39: =E39*INDEX(Assumptions!$C:$E,MATCH("Wallet connect rate",Assumptions!$B:$B,0),MATCH(B39,Assumptions!$C$3:$E$3,0)) | G39: =F39*INDEX(Assumptions!$C:$E,MATCH("USDC readiness rate",Assumptions!$B:$B,0),MATCH(B39,Assumptions!$C$3:$E$3,0)) | H39: =G39*INDEX(Assumptions!$C:$E,MATCH("First purchase conversion",Assumptions!$B:$B,0),MATCH(B39,Assumptions!$C$3:$E$3,0)) | I39: =J38*INDEX(Assumptions!$C:$E,MATCH("Repeat purchase rate",Assumptions!$B:$B,0),MATCH(B39,Assumptions!$C$3:$E$3,0)) | J39: =H39+I39
A40: 3 | B40: Base | C40: =IF(A40<7,1,IF(A40<13,2,IF(A40<24,3,4))) | D40: =INDEX(Assumptions!$C:$E,MATCH("Starting monthly visits",Assumptions!$B:$B,0),MATCH(B40,Assumptions!$C$3:$E$3,0))*POWER(1+INDEX(Assumptions!$C:$E,MATCH("Monthly visit growth",Assumptions!$B:$B,0),MATCH(B40,Assumptions!$C$3:$E$3,0)),A40-1)*C40 | E40: =D40*INDEX(Assumptions!$C:$E,MATCH("Eligible user rate after geo/compliance",Assumptions!$B:$B,0),MATCH(B40,Assumptions!$C$3:$E$3,0)) | F40: =E40*INDEX(Assumptions!$C:$E,MATCH("Wallet connect rate",Assumptions!$B:$B,0),MATCH(B40,Assumptions!$C$3:$E$3,0)) | G40: =F40*INDEX(Assumptions!$C:$E,MATCH("USDC readiness rate",Assumptions!$B:$B,0),MATCH(B40,Assumptions!$C$3:$E$3,0)) | H40: =G40*INDEX(Assumptions!$C:$E,MATCH("First purchase conversion",Assumptions!$B:$B,0),MATCH(B40,Assumptions!$C$3:$E$3,0)) | I40: =J39*INDEX(Assumptions!$C:$E,MATCH("Repeat purchase rate",Assumptions!$B:$B,0),MATCH(B40,Assumptions!$C$3:$E$3,0)) | J40: =H40+I40
A41: 4 | B41: Base | C41: =IF(A41<7,1,IF(A41<13,2,IF(A41<24,3,4))) | D41: =INDEX(Assumptions!$C:$E,MATCH("Starting monthly visits",Assumptions!$B:$B,0),MATCH(B41,Assumptions!$C$3:$E$3,0))*POWER(1+INDEX(Assumptions!$C:$E,MATCH("Monthly visit growth",Assumptions!$B:$B,0),MATCH(B41,Assumptions!$C$3:$E$3,0)),A41-1)*C41 | E41: =D41*INDEX(Assumptions!$C:$E,MATCH("Eligible user rate after geo/compliance",Assumptions!$B:$B,0),MATCH(B41,Assumptions!$C$3:$E$3,0)) | F41: =E41*INDEX(Assumptions!$C:$E,MATCH("Wallet connect rate",Assumptions!$B:$B,0),MATCH(B41,Assumptions!$C$3:$E$3,0)) | G41: =F41*INDEX(Assumptions!$C:$E,MATCH("USDC readiness rate",Assumptions!$B:$B,0),MATCH(B41,Assumptions!$C$3:$E$3,0)) | H41: =G41*INDEX(Assumptions!$C:$E,MATCH("First purchase conversion",Assumptions!$B:$B,0),MATCH(B41,Assumptions!$C$3:$E$3,0)) | I41: =J40*INDEX(Assumptions!$C:$E,MATCH("Repeat purchase rate",Assumptions!$B:$B,0),MATCH(B41,Assumptions!$C$3:$E$3,0)) | J41: =H41+I41
A42: 5 | B42: Base | C42: =IF(A42<7,1,IF(A42<13,2,IF(A42<24,3,4))) | D42: =INDEX(Assumptions!$C:$E,MATCH("Starting monthly visits",Assumptions!$B:$B,0),MATCH(B42,Assumptions!$C$3:$E$3,0))*POWER(1+INDEX(Assumptions!$C:$E,MATCH("Monthly visit growth",Assumptions!$B:$B,0),MATCH(B42,Assumptions!$C$3:$E$3,0)),A42-1)*C42 | E42: =D42*INDEX(Assumptions!$C:$E,MATCH("Eligible user rate after geo/compliance",Assumptions!$B:$B,0),MATCH(B42,Assumptions!$C$3:$E$3,0)) | F42: =E42*INDEX(Assumptions!$C:$E,MATCH("Wallet connect rate",Assumptions!$B:$B,0),MATCH(B42,Assumptions!$C$3:$E$3,0)) | G42: =F42*INDEX(Assumptions!$C:$E,MATCH("USDC readiness rate",Assumptions!$B:$B,0),MATCH(B42,Assumptions!$C$3:$E$3,0)) | H42: =G42*INDEX(Assumptions!$C:$E,MATCH("First purchase conversion",Assumptions!$B:$B,0),MATCH(B42,Assumptions!$C$3:$E$3,0)) | I42: =J41*INDEX(Assumptions!$C:$E,MATCH("Repeat purchase rate",Assumptions!$B:$B,0),MATCH(B42,Assumptions!$C$3:$E$3,0)) | J42: =H42+I42
A43: 6 | B43: Base | C43: =IF(A43<7,1,IF(A43<13,2,IF(A43<24,3,4))) | D43: =INDEX(Assumptions!$C:$E,MATCH("Starting monthly visits",Assumptions!$B:$B,0),MATCH(B43,Assumptions!$C$3:$E$3,0))*POWER(1+INDEX(Assumptions!$C:$E,MATCH("Monthly visit growth",Assumptions!$B:$B,0),MATCH(B43,Assumptions!$C$3:$E$3,0)),A43-1)*C43 | E43: =D43*INDEX(Assumptions!$C:$E,MATCH("Eligible user rate after geo/compliance",Assumptions!$B:$B,0),MATCH(B43,Assumptions!$C$3:$E$3,0)) | F43: =E43*INDEX(Assumptions!$C:$E,MATCH("Wallet connect rate",Assumptions!$B:$B,0),MATCH(B43,Assumptions!$C$3:$E$3,0)) | G43: =F43*INDEX(Assumptions!$C:$E,MATCH("USDC readiness rate",Assumptions!$B:$B,0),MATCH(B43,Assumptions!$C$3:$E$3,0)) | H43: =G43*INDEX(Assumptions!$C:$E,MATCH("First purchase conversion",Assumptions!$B:$B,0),MATCH(B43,Assumptions!$C$3:$E$3,0)) | I43: =J42*INDEX(Assumptions!$C:$E,MATCH("Repeat purchase rate",Assumptions!$B:$B,0),MATCH(B43,Assumptions!$C$3:$E$3,0)) | J43: =H43+I43
A44: 7 | B44: Base | C44: =IF(A44<7,1,IF(A44<13,2,IF(A44<24,3,4))) | D44: =INDEX(Assumptions!$C:$E,MATCH("Starting monthly visits",Assumptions!$B:$B,0),MATCH(B44,Assumptions!$C$3:$E$3,0))*POWER(1+INDEX(Assumptions!$C:$E,MATCH("Monthly visit growth",Assumptions!$B:$B,0),MATCH(B44,Assumptions!$C$3:$E$3,0)),A44-1)*C44 | E44: =D44*INDEX(Assumptions!$C:$E,MATCH("Eligible user rate after geo/compliance",Assumptions!$B:$B,0),MATCH(B44,Assumptions!$C$3:$E$3,0)) | F44: =E44*INDEX(Assumptions!$C:$E,MATCH("Wallet connect rate",Assumptions!$B:$B,0),MATCH(B44,Assumptions!$C$3:$E$3,0)) | G44: =F44*INDEX(Assumptions!$C:$E,MATCH("USDC readiness rate",Assumptions!$B:$B,0),MATCH(B44,Assumptions!$C$3:$E$3,0)) | H44: =G44*INDEX(Assumptions!$C:$E,MATCH("First purchase conversion",Assumptions!$B:$B,0),MATCH(B44,Assumptions!$C$3:$E$3,0)) | I44: =J43*INDEX(Assumptions!$C:$E,MATCH("Repeat purchase rate",Assumptions!$B:$B,0),MATCH(B44,Assumptions!$C$3:$E$3,0)) | J44: =H44+I44
A45: 8 | B45: Base | C45: =IF(A45<7,1,IF(A45<13,2,IF(A45<24,3,4))) | D45: =INDEX(Assumptions!$C:$E,MATCH("Starting monthly visits",Assumptions!$B:$B,0),MATCH(B45,Assumptions!$C$3:$E$3,0))*POWER(1+INDEX(Assumptions!$C:$E,MATCH("Monthly visit growth",Assumptions!$B:$B,0),MATCH(B45,Assumptions!$C$3:$E$3,0)),A45-1)*C45 | E45: =D45*INDEX(Assumptions!$C:$E,MATCH("Eligible user rate after geo/compliance",Assumptions!$B:$B,0),MATCH(B45,Assumptions!$C$3:$E$3,0)) | F45: =E45*INDEX(Assumptions!$C:$E,MATCH("Wallet connect rate",Assumptions!$B:$B,0),MATCH(B45,Assumptions!$C$3:$E$3,0)) | G45: =F45*INDEX(Assumptions!$C:$E,MATCH("USDC readiness rate",Assumptions!$B:$B,0),MATCH(B45,Assumptions!$C$3:$E$3,0)) | H45: =G45*INDEX(Assumptions!$C:$E,MATCH("First purchase conversion",Assumptions!$B:$B,0),MATCH(B45,Assumptions!$C$3:$E$3,0)) | I45: =J44*INDEX(Assumptions!$C:$E,MATCH("Repeat purchase rate",Assumptions!$B:$B,0),MATCH(B45,Assumptions!$C$3:$E$3,0)) | J45: =H45+I45
A46: 9 | B46: Base | C46: =IF(A46<7,1,IF(A46<13,2,IF(A46<24,3,4))) | D46: =INDEX(Assumptions!$C:$E,MATCH("Starting monthly visits",Assumptions!$B:$B,0),MATCH(B46,Assumptions!$C$3:$E$3,0))*POWER(1+INDEX(Assumptions!$C:$E,MATCH("Monthly visit growth",Assumptions!$B:$B,0),MATCH(B46,Assumptions!$C$3:$E$3,0)),A46-1)*C46 | E46: =D46*INDEX(Assumptions!$C:$E,MATCH("Eligible user rate after geo/compliance",Assumptions!$B:$B,0),MATCH(B46,Assumptions!$C$3:$E$3,0)) | F46: =E46*INDEX(Assumptions!$C:$E,MATCH("Wallet connect rate",Assumptions!$B:$B,0),MATCH(B46,Assumptions!$C$3:$E$3,0)) | G46: =F46*INDEX(Assumptions!$C:$E,MATCH("USDC readiness rate",Assumptions!$B:$B,0),MATCH(B46,Assumptions!$C$3:$E$3,0)) | H46: =G46*INDEX(Assumptions!$C:$E,MATCH("First purchase conversion",Assumptions!$B:$B,0),MATCH(B46,Assumptions!$C$3:$E$3,0)) | I46: =J45*INDEX(Assumptions!$C:$E,MATCH("Repeat purchase rate",Assumptions!$B:$B,0),MATCH(B46,Assumptions!$C$3:$E$3,0)) | J46: =H46+I46
A47: 10 | B47: Base | C47: =IF(A47<7,1,IF(A47<13,2,IF(A47<24,3,4))) | D47: =INDEX(Assumptions!$C:$E,MATCH("Starting monthly visits",Assumptions!$B:$B,0),MATCH(B47,Assumptions!$C$3:$E$3,0))*POWER(1+INDEX(Assumptions!$C:$E,MATCH("Monthly visit growth",Assumptions!$B:$B,0),MATCH(B47,Assumptions!$C$3:$E$3,0)),A47-1)*C47 | E47: =D47*INDEX(Assumptions!$C:$E,MATCH("Eligible user rate after geo/compliance",Assumptions!$B:$B,0),MATCH(B47,Assumptions!$C$3:$E$3,0)) | F47: =E47*INDEX(Assumptions!$C:$E,MATCH("Wallet connect rate",Assumptions!$B:$B,0),MATCH(B47,Assumptions!$C$3:$E$3,0)) | G47: =F47*INDEX(Assumptions!$C:$E,MATCH("USDC readiness rate",Assumptions!$B:$B,0),MATCH(B47,Assumptions!$C$3:$E$3,0)) | H47: =G47*INDEX(Assumptions!$C:$E,MATCH("First purchase conversion",Assumptions!$B:$B,0),MATCH(B47,Assumptions!$C$3:$E$3,0)) | I47: =J46*INDEX(Assumptions!$C:$E,MATCH("Repeat purchase rate",Assumptions!$B:$B,0),MATCH(B47,Assumptions!$C$3:$E$3,0)) | J47: =H47+I47
A48: 11 | B48: Base | C48: =IF(A48<7,1,IF(A48<13,2,IF(A48<24,3,4))) | D48: =INDEX(Assumptions!$C:$E,MATCH("Starting monthly visits",Assumptions!$B:$B,0),MATCH(B48,Assumptions!$C$3:$E$3,0))*POWER(1+INDEX(Assumptions!$C:$E,MATCH("Monthly visit growth",Assumptions!$B:$B,0),MATCH(B48,Assumptions!$C$3:$E$3,0)),A48-1)*C48 | E48: =D48*INDEX(Assumptions!$C:$E,MATCH("Eligible user rate after geo/compliance",Assumptions!$B:$B,0),MATCH(B48,Assumptions!$C$3:$E$3,0)) | F48: =E48*INDEX(Assumptions!$C:$E,MATCH("Wallet connect rate",Assumptions!$B:$B,0),MATCH(B48,Assumptions!$C$3:$E$3,0)) | G48: =F48*INDEX(Assumptions!$C:$E,MATCH("USDC readiness rate",Assumptions!$B:$B,0),MATCH(B48,Assumptions!$C$3:$E$3,0)) | H48: =G48*INDEX(Assumptions!$C:$E,MATCH("First purchase conversion",Assumptions!$B:$B,0),MATCH(B48,Assumptions!$C$3:$E$3,0)) | I48: =J47*INDEX(Assumptions!$C:$E,MATCH("Repeat purchase rate",Assumptions!$B:$B,0),MATCH(B48,Assumptions!$C$3:$E$3,0)) | J48: =H48+I48
A49: 12 | B49: Base | C49: =IF(A49<7,1,IF(A49<13,2,IF(A49<24,3,4))) | D49: =INDEX(Assumptions!$C:$E,MATCH("Starting monthly visits",Assumptions!$B:$B,0),MATCH(B49,Assumptions!$C$3:$E$3,0))*POWER(1+INDEX(Assumptions!$C:$E,MATCH("Monthly visit growth",Assumptions!$B:$B,0),MATCH(B49,Assumptions!$C$3:$E$3,0)),A49-1)*C49 | E49: =D49*INDEX(Assumptions!$C:$E,MATCH("Eligible user rate after geo/compliance",Assumptions!$B:$B,0),MATCH(B49,Assumptions!$C$3:$E$3,0)) | F49: =E49*INDEX(Assumptions!$C:$E,MATCH("Wallet connect rate",Assumptions!$B:$B,0),MATCH(B49,Assumptions!$C$3:$E$3,0)) | G49: =F49*INDEX(Assumptions!$C:$E,MATCH("USDC readiness rate",Assumptions!$B:$B,0),MATCH(B49,Assumptions!$C$3:$E$3,0)) | H49: =G49*INDEX(Assumptions!$C:$E,MATCH("First purchase conversion",Assumptions!$B:$B,0),MATCH(B49,Assumptions!$C$3:$E$3,0)) | I49: =J48*INDEX(Assumptions!$C:$E,MATCH("Repeat purchase rate",Assumptions!$B:$B,0),MATCH(B49,Assumptions!$C$3:$E$3,0)) | J49: =H49+I49
A50: 13 | B50: Base | C50: =IF(A50<7,1,IF(A50<13,2,IF(A50<24,3,4))) | D50: =INDEX(Assumptions!$C:$E,MATCH("Starting monthly visits",Assumptions!$B:$B,0),MATCH(B50,Assumptions!$C$3:$E$3,0))*POWER(1+INDEX(Assumptions!$C:$E,MATCH("Monthly visit growth",Assumptions!$B:$B,0),MATCH(B50,Assumptions!$C$3:$E$3,0)),A50-1)*C50 | E50: =D50*INDEX(Assumptions!$C:$E,MATCH("Eligible user rate after geo/compliance",Assumptions!$B:$B,0),MATCH(B50,Assumptions!$C$3:$E$3,0)) | F50: =E50*INDEX(Assumptions!$C:$E,MATCH("Wallet connect rate",Assumptions!$B:$B,0),MATCH(B50,Assumptions!$C$3:$E$3,0)) | G50: =F50*INDEX(Assumptions!$C:$E,MATCH("USDC readiness rate",Assumptions!$B:$B,0),MATCH(B50,Assumptions!$C$3:$E$3,0)) | H50: =G50*INDEX(Assumptions!$C:$E,MATCH("First purchase conversion",Assumptions!$B:$B,0),MATCH(B50,Assumptions!$C$3:$E$3,0)) | I50: =J49*INDEX(Assumptions!$C:$E,MATCH("Repeat purchase rate",Assumptions!$B:$B,0),MATCH(B50,Assumptions!$C$3:$E$3,0)) | J50: =H50+I50
... A73: 36 | B73: Base | C73: =IF(A73<7,1,IF(A73<13,2,IF(A73<24,3,4))) | D73: =INDEX(Assumptions!$C:$E,MATCH("Starting monthly visits",Assumptions!$B:$B,0),MATCH(B73,Assumptions!$C$3:$E$3,0))*POWER(1+INDEX(Assumptions!$C:$E,MATCH("Monthly visit growth",Assumptions!$B:$B,0),MATCH(B73,Assumptions!$C$3:$E$3,0)),A73-1)*C73 | E73: =D73*INDEX(Assumptions!$C:$E,MATCH("Eligible user rate after geo/compliance",Assumptions!$B:$B,0),MATCH(B73,Assumptions!$C$3:$E$3,0)) | F73: =E73*INDEX(Assumptions!$C:$E,MATCH("Wallet connect rate",Assumptions!$B:$B,0),MATCH(B73,Assumptions!$C$3:$E$3,0)) | G73: =F73*INDEX(Assumptions!$C:$E,MATCH("USDC readiness rate",Assumptions!$B:$B,0),MATCH(B73,Assumptions!$C$3:$E$3,0)) | H73: =G73*INDEX(Assumptions!$C:$E,MATCH("First purchase conversion",Assumptions!$B:$B,0),MATCH(B73,Assumptions!$C$3:$E$3,0)) | I73: =J72*INDEX(Assumptions!$C:$E,MATCH("Repeat purchase rate",Assumptions!$B:$B,0),MATCH(B73,Assumptions!$C$3:$E$3,0)) | J73: =H73+I73
A74: 1 | B74: Upside | C74: =IF(A74<7,1,IF(A74<13,2,IF(A74<24,3,4))) | D74: =INDEX(Assumptions!$C:$E,MATCH("Starting monthly visits",Assumptions!$B:$B,0),MATCH(B74,Assumptions!$C$3:$E$3,0))*POWER(1+INDEX(Assumptions!$C:$E,MATCH("Monthly visit growth",Assumptions!$B:$B,0),MATCH(B74,Assumptions!$C$3:$E$3,0)),A74-1)*C74 | E74: =D74*INDEX(Assumptions!$C:$E,MATCH("Eligible user rate after geo/compliance",Assumptions!$B:$B,0),MATCH(B74,Assumptions!$C$3:$E$3,0)) | F74: =E74*INDEX(Assumptions!$C:$E,MATCH("Wallet connect rate",Assumptions!$B:$B,0),MATCH(B74,Assumptions!$C$3:$E$3,0)) | G74: =F74*INDEX(Assumptions!$C:$E,MATCH("USDC readiness rate",Assumptions!$B:$B,0),MATCH(B74,Assumptions!$C$3:$E$3,0)) | H74: =G74*INDEX(Assumptions!$C:$E,MATCH("First purchase conversion",Assumptions!$B:$B,0),MATCH(B74,Assumptions!$C$3:$E$3,0)) | I74: =0*INDEX(Assumptions!$C:$E,MATCH("Repeat purchase rate",Assumptions!$B:$B,0),MATCH(B74,Assumptions!$C$3:$E$3,0)) | J74: =H74+I74
A75: 2 | B75: Upside | C75: =IF(A75<7,1,IF(A75<13,2,IF(A75<24,3,4))) | D75: =INDEX(Assumptions!$C:$E,MATCH("Starting monthly visits",Assumptions!$B:$B,0),MATCH(B75,Assumptions!$C$3:$E$3,0))*POWER(1+INDEX(Assumptions!$C:$E,MATCH("Monthly visit growth",Assumptions!$B:$B,0),MATCH(B75,Assumptions!$C$3:$E$3,0)),A75-1)*C75 | E75: =D75*INDEX(Assumptions!$C:$E,MATCH("Eligible user rate after geo/compliance",Assumptions!$B:$B,0),MATCH(B75,Assumptions!$C$3:$E$3,0)) | F75: =E75*INDEX(Assumptions!$C:$E,MATCH("Wallet connect rate",Assumptions!$B:$B,0),MATCH(B75,Assumptions!$C$3:$E$3,0)) | G75: =F75*INDEX(Assumptions!$C:$E,MATCH("USDC readiness rate",Assumptions!$B:$B,0),MATCH(B75,Assumptions!$C$3:$E$3,0)) | H75: =G75*INDEX(Assumptions!$C:$E,MATCH("First purchase conversion",Assumptions!$B:$B,0),MATCH(B75,Assumptions!$C$3:$E$3,0)) | I75: =J74*INDEX(Assumptions!$C:$E,MATCH("Repeat purchase rate",Assumptions!$B:$B,0),MATCH(B75,Assumptions!$C$3:$E$3,0)) | J75: =H75+I75
A76: 3 | B76: Upside | C76: =IF(A76<7,1,IF(A76<13,2,IF(A76<24,3,4))) | D76: =INDEX(Assumptions!$C:$E,MATCH("Starting monthly visits",Assumptions!$B:$B,0),MATCH(B76,Assumptions!$C$3:$E$3,0))*POWER(1+INDEX(Assumptions!$C:$E,MATCH("Monthly visit growth",Assumptions!$B:$B,0),MATCH(B76,Assumptions!$C$3:$E$3,0)),A76-1)*C76 | E76: =D76*INDEX(Assumptions!$C:$E,MATCH("Eligible user rate after geo/compliance",Assumptions!$B:$B,0),MATCH(B76,Assumptions!$C$3:$E$3,0)) | F76: =E76*INDEX(Assumptions!$C:$E,MATCH("Wallet connect rate",Assumptions!$B:$B,0),MATCH(B76,Assumptions!$C$3:$E$3,0)) | G76: =F76*INDEX(Assumptions!$C:$E,MATCH("USDC readiness rate",Assumptions!$B:$B,0),MATCH(B76,Assumptions!$C$3:$E$3,0)) | H76: =G76*INDEX(Assumptions!$C:$E,MATCH("First purchase conversion",Assumptions!$B:$B,0),MATCH(B76,Assumptions!$C$3:$E$3,0)) | I76: =J75*INDEX(Assumptions!$C:$E,MATCH("Repeat purchase rate",Assumptions!$B:$B,0),MATCH(B76,Assumptions!$C$3:$E$3,0)) | J76: =H76+I76
A77: 4 | B77: Upside | C77: =IF(A77<7,1,IF(A77<13,2,IF(A77<24,3,4))) | D77: =INDEX(Assumptions!$C:$E,MATCH("Starting monthly visits",Assumptions!$B:$B,0),MATCH(B77,Assumptions!$C$3:$E$3,0))*POWER(1+INDEX(Assumptions!$C:$E,MATCH("Monthly visit growth",Assumptions!$B:$B,0),MATCH(B77,Assumptions!$C$3:$E$3,0)),A77-1)*C77 | E77: =D77*INDEX(Assumptions!$C:$E,MATCH("Eligible user rate after geo/compliance",Assumptions!$B:$B,0),MATCH(B77,Assumptions!$C$3:$E$3,0)) | F77: =E77*INDEX(Assumptions!$C:$E,MATCH("Wallet connect rate",Assumptions!$B:$B,0),MATCH(B77,Assumptions!$C$3:$E$3,0)) | G77: =F77*INDEX(Assumptions!$C:$E,MATCH("USDC readiness rate",Assumptions!$B:$B,0),MATCH(B77,Assumptions!$C$3:$E$3,0)) | H77: =G77*INDEX(Assumptions!$C:$E,MATCH("First purchase conversion",Assumptions!$B:$B,0),MATCH(B77,Assumptions!$C$3:$E$3,0)) | I77: =J76*INDEX(Assumptions!$C:$E,MATCH("Repeat purchase rate",Assumptions!$B:$B,0),MATCH(B77,Assumptions!$C$3:$E$3,0)) | J77: =H77+I77
A78: 5 | B78: Upside | C78: =IF(A78<7,1,IF(A78<13,2,IF(A78<24,3,4))) | D78: =INDEX(Assumptions!$C:$E,MATCH("Starting monthly visits",Assumptions!$B:$B,0),MATCH(B78,Assumptions!$C$3:$E$3,0))*POWER(1+INDEX(Assumptions!$C:$E,MATCH("Monthly visit growth",Assumptions!$B:$B,0),MATCH(B78,Assumptions!$C$3:$E$3,0)),A78-1)*C78 | E78: =D78*INDEX(Assumptions!$C:$E,MATCH("Eligible user rate after geo/compliance",Assumptions!$B:$B,0),MATCH(B78,Assumptions!$C$3:$E$3,0)) | F78: =E78*INDEX(Assumptions!$C:$E,MATCH("Wallet connect rate",Assumptions!$B:$B,0),MATCH(B78,Assumptions!$C$3:$E$3,0)) | G78: =F78*INDEX(Assumptions!$C:$E,MATCH("USDC readiness rate",Assumptions!$B:$B,0),MATCH(B78,Assumptions!$C$3:$E$3,0)) | H78: =G78*INDEX(Assumptions!$C:$E,MATCH("First purchase conversion",Assumptions!$B:$B,0),MATCH(B78,Assumptions!$C$3:$E$3,0)) | I78: =J77*INDEX(Assumptions!$C:$E,MATCH("Repeat purchase rate",Assumptions!$B:$B,0),MATCH(B78,Assumptions!$C$3:$E$3,0)) | J78: =H78+I78
A79: 6 | B79: Upside | C79: =IF(A79<7,1,IF(A79<13,2,IF(A79<24,3,4))) | D79: =INDEX(Assumptions!$C:$E,MATCH("Starting monthly visits",Assumptions!$B:$B,0),MATCH(B79,Assumptions!$C$3:$E$3,0))*POWER(1+INDEX(Assumptions!$C:$E,MATCH("Monthly visit growth",Assumptions!$B:$B,0),MATCH(B79,Assumptions!$C$3:$E$3,0)),A79-1)*C79 | E79: =D79*INDEX(Assumptions!$C:$E,MATCH("Eligible user rate after geo/compliance",Assumptions!$B:$B,0),MATCH(B79,Assumptions!$C$3:$E$3,0)) | F79: =E79*INDEX(Assumptions!$C:$E,MATCH("Wallet connect rate",Assumptions!$B:$B,0),MATCH(B79,Assumptions!$C$3:$E$3,0)) | G79: =F79*INDEX(Assumptions!$C:$E,MATCH("USDC readiness rate",Assumptions!$B:$B,0),MATCH(B79,Assumptions!$C$3:$E$3,0)) | H79: =G79*INDEX(Assumptions!$C:$E,MATCH("First purchase conversion",Assumptions!$B:$B,0),MATCH(B79,Assumptions!$C$3:$E$3,0)) | I79: =J78*INDEX(Assumptions!$C:$E,MATCH("Repeat purchase rate",Assumptions!$B:$B,0),MATCH(B79,Assumptions!$C$3:$E$3,0)) | J79: =H79+I79
A80: 7 | B80: Upside | C80: =IF(A80<7,1,IF(A80<13,2,IF(A80<24,3,4))) | D80: =INDEX(Assumptions!$C:$E,MATCH("Starting monthly visits",Assumptions!$B:$B,0),MATCH(B80,Assumptions!$C$3:$E$3,0))*POWER(1+INDEX(Assumptions!$C:$E,MATCH("Monthly visit growth",Assumptions!$B:$B,0),MATCH(B80,Assumptions!$C$3:$E$3,0)),A80-1)*C80 | E80: =D80*INDEX(Assumptions!$C:$E,MATCH("Eligible user rate after geo/compliance",Assumptions!$B:$B,0),MATCH(B80,Assumptions!$C$3:$E$3,0)) | F80: =E80*INDEX(Assumptions!$C:$E,MATCH("Wallet connect rate",Assumptions!$B:$B,0),MATCH(B80,Assumptions!$C$3:$E$3,0)) | G80: =F80*INDEX(Assumptions!$C:$E,MATCH("USDC readiness rate",Assumptions!$B:$B,0),MATCH(B80,Assumptions!$C$3:$E$3,0)) | H80: =G80*INDEX(Assumptions!$C:$E,MATCH("First purchase conversion",Assumptions!$B:$B,0),MATCH(B80,Assumptions!$C$3:$E$3,0)) | I80: =J79*INDEX(Assumptions!$C:$E,MATCH("Repeat purchase rate",Assumptions!$B:$B,0),MATCH(B80,Assumptions!$C$3:$E$3,0)) | J80: =H80+I80
A81: 8 | B81: Upside | C81: =IF(A81<7,1,IF(A81<13,2,IF(A81<24,3,4))) | D81: =INDEX(Assumptions!$C:$E,MATCH("Starting monthly visits",Assumptions!$B:$B,0),MATCH(B81,Assumptions!$C$3:$E$3,0))*POWER(1+INDEX(Assumptions!$C:$E,MATCH("Monthly visit growth",Assumptions!$B:$B,0),MATCH(B81,Assumptions!$C$3:$E$3,0)),A81-1)*C81 | E81: =D81*INDEX(Assumptions!$C:$E,MATCH("Eligible user rate after geo/compliance",Assumptions!$B:$B,0),MATCH(B81,Assumptions!$C$3:$E$3,0)) | F81: =E81*INDEX(Assumptions!$C:$E,MATCH("Wallet connect rate",Assumptions!$B:$B,0),MATCH(B81,Assumptions!$C$3:$E$3,0)) | G81: =F81*INDEX(Assumptions!$C:$E,MATCH("USDC readiness rate",Assumptions!$B:$B,0),MATCH(B81,Assumptions!$C$3:$E$3,0)) | H81: =G81*INDEX(Assumptions!$C:$E,MATCH("First purchase conversion",Assumptions!$B:$B,0),MATCH(B81,Assumptions!$C$3:$E$3,0)) | I81: =J80*INDEX(Assumptions!$C:$E,MATCH("Repeat purchase rate",Assumptions!$B:$B,0),MATCH(B81,Assumptions!$C$3:$E$3,0)) | J81: =H81+I81
A82: 9 | B82: Upside | C82: =IF(A82<7,1,IF(A82<13,2,IF(A82<24,3,4))) | D82: =INDEX(Assumptions!$C:$E,MATCH("Starting monthly visits",Assumptions!$B:$B,0),MATCH(B82,Assumptions!$C$3:$E$3,0))*POWER(1+INDEX(Assumptions!$C:$E,MATCH("Monthly visit growth",Assumptions!$B:$B,0),MATCH(B82,Assumptions!$C$3:$E$3,0)),A82-1)*C82 | E82: =D82*INDEX(Assumptions!$C:$E,MATCH("Eligible user rate after geo/compliance",Assumptions!$B:$B,0),MATCH(B82,Assumptions!$C$3:$E$3,0)) | F82: =E82*INDEX(Assumptions!$C:$E,MATCH("Wallet connect rate",Assumptions!$B:$B,0),MATCH(B82,Assumptions!$C$3:$E$3,0)) | G82: =F82*INDEX(Assumptions!$C:$E,MATCH("USDC readiness rate",Assumptions!$B:$B,0),MATCH(B82,Assumptions!$C$3:$E$3,0)) | H82: =G82*INDEX(Assumptions!$C:$E,MATCH("First purchase conversion",Assumptions!$B:$B,0),MATCH(B82,Assumptions!$C$3:$E$3,0)) | I82: =J81*INDEX(Assumptions!$C:$E,MATCH("Repeat purchase rate",Assumptions!$B:$B,0),MATCH(B82,Assumptions!$C$3:$E$3,0)) | J82: =H82+I82
A83: 10 | B83: Upside | C83: =IF(A83<7,1,IF(A83<13,2,IF(A83<24,3,4))) | D83: =INDEX(Assumptions!$C:$E,MATCH("Starting monthly visits",Assumptions!$B:$B,0),MATCH(B83,Assumptions!$C$3:$E$3,0))*POWER(1+INDEX(Assumptions!$C:$E,MATCH("Monthly visit growth",Assumptions!$B:$B,0),MATCH(B83,Assumptions!$C$3:$E$3,0)),A83-1)*C83 | E83: =D83*INDEX(Assumptions!$C:$E,MATCH("Eligible user rate after geo/compliance",Assumptions!$B:$B,0),MATCH(B83,Assumptions!$C$3:$E$3,0)) | F83: =E83*INDEX(Assumptions!$C:$E,MATCH("Wallet connect rate",Assumptions!$B:$B,0),MATCH(B83,Assumptions!$C$3:$E$3,0)) | G83: =F83*INDEX(Assumptions!$C:$E,MATCH("USDC readiness rate",Assumptions!$B:$B,0),MATCH(B83,Assumptions!$C$3:$E$3,0)) | H83: =G83*INDEX(Assumptions!$C:$E,MATCH("First purchase conversion",Assumptions!$B:$B,0),MATCH(B83,Assumptions!$C$3:$E$3,0)) | I83: =J82*INDEX(Assumptions!$C:$E,MATCH("Repeat purchase rate",Assumptions!$B:$B,0),MATCH(B83,Assumptions!$C$3:$E$3,0)) | J83: =H83+I83
A84: 11 | B84: Upside | C84: =IF(A84<7,1,IF(A84<13,2,IF(A84<24,3,4))) | D84: =INDEX(Assumptions!$C:$E,MATCH("Starting monthly visits",Assumptions!$B:$B,0),MATCH(B84,Assumptions!$C$3:$E$3,0))*POWER(1+INDEX(Assumptions!$C:$E,MATCH("Monthly visit growth",Assumptions!$B:$B,0),MATCH(B84,Assumptions!$C$3:$E$3,0)),A84-1)*C84 | E84: =D84*INDEX(Assumptions!$C:$E,MATCH("Eligible user rate after geo/compliance",Assumptions!$B:$B,0),MATCH(B84,Assumptions!$C$3:$E$3,0)) | F84: =E84*INDEX(Assumptions!$C:$E,MATCH("Wallet connect rate",Assumptions!$B:$B,0),MATCH(B84,Assumptions!$C$3:$E$3,0)) | G84: =F84*INDEX(Assumptions!$C:$E,MATCH("USDC readiness rate",Assumptions!$B:$B,0),MATCH(B84,Assumptions!$C$3:$E$3,0)) | H84: =G84*INDEX(Assumptions!$C:$E,MATCH("First purchase conversion",Assumptions!$B:$B,0),MATCH(B84,Assumptions!$C$3:$E$3,0)) | I84: =J83*INDEX(Assumptions!$C:$E,MATCH("Repeat purchase rate",Assumptions!$B:$B,0),MATCH(B84,Assumptions!$C$3:$E$3,0)) | J84: =H84+I84
...

Sheet Revenue
A1: Month | B1: Scenario | C1: Active users | D1: Tickets sold | E1: Average ticket | F1: GMV | G1: Prize pool | H1: Platform fee | I1: Jackpot contribution | J1: Gas reserve | K1: Net platform revenue before OPEX
A2: 1 | B2: Conservative | C2: =SUMIFS(Funnel!$J:$J,Funnel!$A:$A,A2,Funnel!$B:$B,B2) | D2: =C2*INDEX(Assumptions!$C:$E,MATCH("Tickets per active user per month",Assumptions!$B:$B,0),MATCH(B2,Assumptions!$C$3:$E$3,0)) | E2: =INDEX(Assumptions!$C:$E,MATCH("Average ticket",Assumptions!$B:$B,0),MATCH(B2,Assumptions!$C$3:$E$3,0)) | F2: =D2*E2 | G2: =F2*INDEX(Assumptions!$C:$E,MATCH("Prize pool share",Assumptions!$B:$B,0),MATCH(B2,Assumptions!$C$3:$E$3,0)) | H2: =F2*INDEX(Assumptions!$C:$E,MATCH("Platform fee share",Assumptions!$B:$B,0),MATCH(B2,Assumptions!$C$3:$E$3,0)) | I2: =F2*INDEX(Assumptions!$C:$E,MATCH("Jackpot contribution share",Assumptions!$B:$B,0),MATCH(B2,Assumptions!$C$3:$E$3,0)) | J2: =H2*INDEX(Assumptions!$C:$E,MATCH("Gas reserve share of platform fee",Assumptions!$B:$B,0),MATCH(B2,Assumptions!$C$3:$E$3,0)) | K2: =H2-J2
A3: 2 | B3: Conservative | C3: =SUMIFS(Funnel!$J:$J,Funnel!$A:$A,A3,Funnel!$B:$B,B3) | D3: =C3*INDEX(Assumptions!$C:$E,MATCH("Tickets per active user per month",Assumptions!$B:$B,0),MATCH(B3,Assumptions!$C$3:$E$3,0)) | E3: =INDEX(Assumptions!$C:$E,MATCH("Average ticket",Assumptions!$B:$B,0),MATCH(B3,Assumptions!$C$3:$E$3,0)) | F3: =D3*E3 | G3: =F3*INDEX(Assumptions!$C:$E,MATCH("Prize pool share",Assumptions!$B:$B,0),MATCH(B3,Assumptions!$C$3:$E$3,0)) | H3: =F3*INDEX(Assumptions!$C:$E,MATCH("Platform fee share",Assumptions!$B:$B,0),MATCH(B3,Assumptions!$C$3:$E$3,0)) | I3: =F3*INDEX(Assumptions!$C:$E,MATCH("Jackpot contribution share",Assumptions!$B:$B,0),MATCH(B3,Assumptions!$C$3:$E$3,0)) | J3: =H3*INDEX(Assumptions!$C:$E,MATCH("Gas reserve share of platform fee",Assumptions!$B:$B,0),MATCH(B3,Assumptions!$C$3:$E$3,0)) | K3: =H3-J3
A4: 3 | B4: Conservative | C4: =SUMIFS(Funnel!$J:$J,Funnel!$A:$A,A4,Funnel!$B:$B,B4) | D4: =C4*INDEX(Assumptions!$C:$E,MATCH("Tickets per active user per month",Assumptions!$B:$B,0),MATCH(B4,Assumptions!$C$3:$E$3,0)) | E4: =INDEX(Assumptions!$C:$E,MATCH("Average ticket",Assumptions!$B:$B,0),MATCH(B4,Assumptions!$C$3:$E$3,0)) | F4: =D4*E4 | G4: =F4*INDEX(Assumptions!$C:$E,MATCH("Prize pool share",Assumptions!$B:$B,0),MATCH(B4,Assumptions!$C$3:$E$3,0)) | H4: =F4*INDEX(Assumptions!$C:$E,MATCH("Platform fee share",Assumptions!$B:$B,0),MATCH(B4,Assumptions!$C$3:$E$3,0)) | I4: =F4*INDEX(Assumptions!$C:$E,MATCH("Jackpot contribution share",Assumptions!$B:$B,0),MATCH(B4,Assumptions!$C$3:$E$3,0)) | J4: =H4*INDEX(Assumptions!$C:$E,MATCH("Gas reserve share of platform fee",Assumptions!$B:$B,0),MATCH(B4,Assumptions!$C$3:$E$3,0)) | K4: =H4-J4
A5: 4 | B5: Conservative | C5: =SUMIFS(Funnel!$J:$J,Funnel!$A:$A,A5,Funnel!$B:$B,B5) | D5: =C5*INDEX(Assumptions!$C:$E,MATCH("Tickets per active user per month",Assumptions!$B:$B,0),MATCH(B5,Assumptions!$C$3:$E$3,0)) | E5: =INDEX(Assumptions!$C:$E,MATCH("Average ticket",Assumptions!$B:$B,0),MATCH(B5,Assumptions!$C$3:$E$3,0)) | F5: =D5*E5 | G5: =F5*INDEX(Assumptions!$C:$E,MATCH("Prize pool share",Assumptions!$B:$B,0),MATCH(B5,Assumptions!$C$3:$E$3,0)) | H5: =F5*INDEX(Assumptions!$C:$E,MATCH("Platform fee share",Assumptions!$B:$B,0),MATCH(B5,Assumptions!$C$3:$E$3,0)) | I5: =F5*INDEX(Assumptions!$C:$E,MATCH("Jackpot contribution share",Assumptions!$B:$B,0),MATCH(B5,Assumptions!$C$3:$E$3,0)) | J5: =H5*INDEX(Assumptions!$C:$E,MATCH("Gas reserve share of platform fee",Assumptions!$B:$B,0),MATCH(B5,Assumptions!$C$3:$E$3,0)) | K5: =H5-J5
A6: 5 | B6: Conservative | C6: =SUMIFS(Funnel!$J:$J,Funnel!$A:$A,A6,Funnel!$B:$B,B6) | D6: =C6*INDEX(Assumptions!$C:$E,MATCH("Tickets per active user per month",Assumptions!$B:$B,0),MATCH(B6,Assumptions!$C$3:$E$3,0)) | E6: =INDEX(Assumptions!$C:$E,MATCH("Average ticket",Assumptions!$B:$B,0),MATCH(B6,Assumptions!$C$3:$E$3,0)) | F6: =D6*E6 | G6: =F6*INDEX(Assumptions!$C:$E,MATCH("Prize pool share",Assumptions!$B:$B,0),MATCH(B6,Assumptions!$C$3:$E$3,0)) | H6: =F6*INDEX(Assumptions!$C:$E,MATCH("Platform fee share",Assumptions!$B:$B,0),MATCH(B6,Assumptions!$C$3:$E$3,0)) | I6: =F6*INDEX(Assumptions!$C:$E,MATCH("Jackpot contribution share",Assumptions!$B:$B,0),MATCH(B6,Assumptions!$C$3:$E$3,0)) | J6: =H6*INDEX(Assumptions!$C:$E,MATCH("Gas reserve share of platform fee",Assumptions!$B:$B,0),MATCH(B6,Assumptions!$C$3:$E$3,0)) | K6: =H6-J6
A7: 6 | B7: Conservative | C7: =SUMIFS(Funnel!$J:$J,Funnel!$A:$A,A7,Funnel!$B:$B,B7) | D7: =C7*INDEX(Assumptions!$C:$E,MATCH("Tickets per active user per month",Assumptions!$B:$B,0),MATCH(B7,Assumptions!$C$3:$E$3,0)) | E7: =INDEX(Assumptions!$C:$E,MATCH("Average ticket",Assumptions!$B:$B,0),MATCH(B7,Assumptions!$C$3:$E$3,0)) | F7: =D7*E7 | G7: =F7*INDEX(Assumptions!$C:$E,MATCH("Prize pool share",Assumptions!$B:$B,0),MATCH(B7,Assumptions!$C$3:$E$3,0)) | H7: =F7*INDEX(Assumptions!$C:$E,MATCH("Platform fee share",Assumptions!$B:$B,0),MATCH(B7,Assumptions!$C$3:$E$3,0)) | I7: =F7*INDEX(Assumptions!$C:$E,MATCH("Jackpot contribution share",Assumptions!$B:$B,0),MATCH(B7,Assumptions!$C$3:$E$3,0)) | J7: =H7*INDEX(Assumptions!$C:$E,MATCH("Gas reserve share of platform fee",Assumptions!$B:$B,0),MATCH(B7,Assumptions!$C$3:$E$3,0)) | K7: =H7-J7
A8: 7 | B8: Conservative | C8: =SUMIFS(Funnel!$J:$J,Funnel!$A:$A,A8,Funnel!$B:$B,B8) | D8: =C8*INDEX(Assumptions!$C:$E,MATCH("Tickets per active user per month",Assumptions!$B:$B,0),MATCH(B8,Assumptions!$C$3:$E$3,0)) | E8: =INDEX(Assumptions!$C:$E,MATCH("Average ticket",Assumptions!$B:$B,0),MATCH(B8,Assumptions!$C$3:$E$3,0)) | F8: =D8*E8 | G8: =F8*INDEX(Assumptions!$C:$E,MATCH("Prize pool share",Assumptions!$B:$B,0),MATCH(B8,Assumptions!$C$3:$E$3,0)) | H8: =F8*INDEX(Assumptions!$C:$E,MATCH("Platform fee share",Assumptions!$B:$B,0),MATCH(B8,Assumptions!$C$3:$E$3,0)) | I8: =F8*INDEX(Assumptions!$C:$E,MATCH("Jackpot contribution share",Assumptions!$B:$B,0),MATCH(B8,Assumptions!$C$3:$E$3,0)) | J8: =H8*INDEX(Assumptions!$C:$E,MATCH("Gas reserve share of platform fee",Assumptions!$B:$B,0),MATCH(B8,Assumptions!$C$3:$E$3,0)) | K8: =H8-J8
A9: 8 | B9: Conservative | C9: =SUMIFS(Funnel!$J:$J,Funnel!$A:$A,A9,Funnel!$B:$B,B9) | D9: =C9*INDEX(Assumptions!$C:$E,MATCH("Tickets per active user per month",Assumptions!$B:$B,0),MATCH(B9,Assumptions!$C$3:$E$3,0)) | E9: =INDEX(Assumptions!$C:$E,MATCH("Average ticket",Assumptions!$B:$B,0),MATCH(B9,Assumptions!$C$3:$E$3,0)) | F9: =D9*E9 | G9: =F9*INDEX(Assumptions!$C:$E,MATCH("Prize pool share",Assumptions!$B:$B,0),MATCH(B9,Assumptions!$C$3:$E$3,0)) | H9: =F9*INDEX(Assumptions!$C:$E,MATCH("Platform fee share",Assumptions!$B:$B,0),MATCH(B9,Assumptions!$C$3:$E$3,0)) | I9: =F9*INDEX(Assumptions!$C:$E,MATCH("Jackpot contribution share",Assumptions!$B:$B,0),MATCH(B9,Assumptions!$C$3:$E$3,0)) | J9: =H9*INDEX(Assumptions!$C:$E,MATCH("Gas reserve share of platform fee",Assumptions!$B:$B,0),MATCH(B9,Assumptions!$C$3:$E$3,0)) | K9: =H9-J9
A10: 9 | B10: Conservative | C10: =SUMIFS(Funnel!$J:$J,Funnel!$A:$A,A10,Funnel!$B:$B,B10) | D10: =C10*INDEX(Assumptions!$C:$E,MATCH("Tickets per active user per month",Assumptions!$B:$B,0),MATCH(B10,Assumptions!$C$3:$E$3,0)) | E10: =INDEX(Assumptions!$C:$E,MATCH("Average ticket",Assumptions!$B:$B,0),MATCH(B10,Assumptions!$C$3:$E$3,0)) | F10: =D10*E10 | G10: =F10*INDEX(Assumptions!$C:$E,MATCH("Prize pool share",Assumptions!$B:$B,0),MATCH(B10,Assumptions!$C$3:$E$3,0)) | H10: =F10*INDEX(Assumptions!$C:$E,MATCH("Platform fee share",Assumptions!$B:$B,0),MATCH(B10,Assumptions!$C$3:$E$3,0)) | I10: =F10*INDEX(Assumptions!$C:$E,MATCH("Jackpot contribution share",Assumptions!$B:$B,0),MATCH(B10,Assumptions!$C$3:$E$3,0)) | J10: =H10*INDEX(Assumptions!$C:$E,MATCH("Gas reserve share of platform fee",Assumptions!$B:$B,0),MATCH(B10,Assumptions!$C$3:$E$3,0)) | K10: =H10-J10
A11: 10 | B11: Conservative | C11: =SUMIFS(Funnel!$J:$J,Funnel!$A:$A,A11,Funnel!$B:$B,B11) | D11: =C11*INDEX(Assumptions!$C:$E,MATCH("Tickets per active user per month",Assumptions!$B:$B,0),MATCH(B11,Assumptions!$C$3:$E$3,0)) | E11: =INDEX(Assumptions!$C:$E,MATCH("Average ticket",Assumptions!$B:$B,0),MATCH(B11,Assumptions!$C$3:$E$3,0)) | F11: =D11*E11 | G11: =F11*INDEX(Assumptions!$C:$E,MATCH("Prize pool share",Assumptions!$B:$B,0),MATCH(B11,Assumptions!$C$3:$E$3,0)) | H11: =F11*INDEX(Assumptions!$C:$E,MATCH("Platform fee share",Assumptions!$B:$B,0),MATCH(B11,Assumptions!$C$3:$E$3,0)) | I11: =F11*INDEX(Assumptions!$C:$E,MATCH("Jackpot contribution share",Assumptions!$B:$B,0),MATCH(B11,Assumptions!$C$3:$E$3,0)) | J11: =H11*INDEX(Assumptions!$C:$E,MATCH("Gas reserve share of platform fee",Assumptions!$B:$B,0),MATCH(B11,Assumptions!$C$3:$E$3,0)) | K11: =H11-J11
A12: 11 | B12: Conservative | C12: =SUMIFS(Funnel!$J:$J,Funnel!$A:$A,A12,Funnel!$B:$B,B12) | D12: =C12*INDEX(Assumptions!$C:$E,MATCH("Tickets per active user per month",Assumptions!$B:$B,0),MATCH(B12,Assumptions!$C$3:$E$3,0)) | E12: =INDEX(Assumptions!$C:$E,MATCH("Average ticket",Assumptions!$B:$B,0),MATCH(B12,Assumptions!$C$3:$E$3,0)) | F12: =D12*E12 | G12: =F12*INDEX(Assumptions!$C:$E,MATCH("Prize pool share",Assumptions!$B:$B,0),MATCH(B12,Assumptions!$C$3:$E$3,0)) | H12: =F12*INDEX(Assumptions!$C:$E,MATCH("Platform fee share",Assumptions!$B:$B,0),MATCH(B12,Assumptions!$C$3:$E$3,0)) | I12: =F12*INDEX(Assumptions!$C:$E,MATCH("Jackpot contribution share",Assumptions!$B:$B,0),MATCH(B12,Assumptions!$C$3:$E$3,0)) | J12: =H12*INDEX(Assumptions!$C:$E,MATCH("Gas reserve share of platform fee",Assumptions!$B:$B,0),MATCH(B12,Assumptions!$C$3:$E$3,0)) | K12: =H12-J12
A13: 12 | B13: Conservative | C13: =SUMIFS(Funnel!$J:$J,Funnel!$A:$A,A13,Funnel!$B:$B,B13) | D13: =C13*INDEX(Assumptions!$C:$E,MATCH("Tickets per active user per month",Assumptions!$B:$B,0),MATCH(B13,Assumptions!$C$3:$E$3,0)) | E13: =INDEX(Assumptions!$C:$E,MATCH("Average ticket",Assumptions!$B:$B,0),MATCH(B13,Assumptions!$C$3:$E$3,0)) | F13: =D13*E13 | G13: =F13*INDEX(Assumptions!$C:$E,MATCH("Prize pool share",Assumptions!$B:$B,0),MATCH(B13,Assumptions!$C$3:$E$3,0)) | H13: =F13*INDEX(Assumptions!$C:$E,MATCH("Platform fee share",Assumptions!$B:$B,0),MATCH(B13,Assumptions!$C$3:$E$3,0)) | I13: =F13*INDEX(Assumptions!$C:$E,MATCH("Jackpot contribution share",Assumptions!$B:$B,0),MATCH(B13,Assumptions!$C$3:$E$3,0)) | J13: =H13*INDEX(Assumptions!$C:$E,MATCH("Gas reserve share of platform fee",Assumptions!$B:$B,0),MATCH(B13,Assumptions!$C$3:$E$3,0)) | K13: =H13-J13
... A109: 36 | B109: Upside | C109: =SUMIFS(Funnel!$J:$J,Funnel!$A:$A,A109,Funnel!$B:$B,B109) | D109: =C109*INDEX(Assumptions!$C:$E,MATCH("Tickets per active user per month",Assumptions!$B:$B,0),MATCH(B109,Assumptions!$C$3:$E$3,0)) | E109: =INDEX(Assumptions!$C:$E,MATCH("Average ticket",Assumptions!$B:$B,0),MATCH(B109,Assumptions!$C$3:$E$3,0)) | F109: =D109*E109 | G109: =F109*INDEX(Assumptions!$C:$E,MATCH("Prize pool share",Assumptions!$B:$B,0),MATCH(B109,Assumptions!$C$3:$E$3,0)) | H109: =F109*INDEX(Assumptions!$C:$E,MATCH("Platform fee share",Assumptions!$B:$B,0),MATCH(B109,Assumptions!$C$3:$E$3,0)) | I109: =F109*INDEX(Assumptions!$C:$E,MATCH("Jackpot contribution share",Assumptions!$B:$B,0),MATCH(B109,Assumptions!$C$3:$E$3,0)) | J109: =H109*INDEX(Assumptions!$C:$E,MATCH("Gas reserve share of platform fee",Assumptions!$B:$B,0),MATCH(B109,Assumptions!$C$3:$E$3,0)) | K109: =H109-J109

Sheet Costs
A1: Month | B1: Scenario | C1: First buyers | D1: Active users | E1: CPA cost | F1: Marketing fixed | G1: KYC cost | H1: Support variable | I1: Product/dev/ops | J1: Legal/compliance | K1: Oracle/data | L1: Infrastructure | M1: Audit/security | N1: Jackpot top-up reserve | O1: Total costs
A2: 1 | B2: Conservative | C2: =SUMIFS(Funnel!$H:$H,Funnel!$A:$A,A2,Funnel!$B:$B,B2) | D2: =SUMIFS(Funnel!$J:$J,Funnel!$A:$A,A2,Funnel!$B:$B,B2) | E2: =C2*INDEX(Assumptions!$C:$E,MATCH("Partner share of first buyers",Assumptions!$B:$B,0),MATCH(B2,Assumptions!$C$3:$E$3,0))*INDEX(Assumptions!$C:$E,MATCH("CPA per qualified player",Assumptions!$B:$B,0),MATCH(B2,Assumptions!$C$3:$E$3,0))*INDEX(Assumptions!$C:$E,MATCH("CPA approved rate",Assumptions!$B:$B,0),MATCH(B2,Assumptions!$C$3:$E$3,0)) | F2: =INDEX(Assumptions!$C:$E,MATCH("Monthly marketing fixed budget",Assumptions!$B:$B,0),MATCH(B2,Assumptions!$C$3:$E$3,0)) | G2: =D2*INDEX(Assumptions!$C:$E,MATCH("KYC required rate",Assumptions!$B:$B,0),MATCH(B2,Assumptions!$C$3:$E$3,0))*INDEX(Assumptions!$C:$E,MATCH("KYC cost per checked user",Assumptions!$B:$B,0),MATCH(B2,Assumptions!$C$3:$E$3,0)) | H2: =D2*INDEX(Assumptions!$C:$E,MATCH("Support cost per active user",Assumptions!$B:$B,0),MATCH(B2,Assumptions!$C$3:$E$3,0)) | I2: =INDEX(Assumptions!$C:$E,MATCH("Monthly product/dev/ops cost",Assumptions!$B:$B,0),MATCH(B2,Assumptions!$C$3:$E$3,0)) | J2: =INDEX(Assumptions!$C:$E,MATCH("Monthly legal/compliance reserve",Assumptions!$B:$B,0),MATCH(B2,Assumptions!$C$3:$E$3,0)) | K2: =INDEX(Assumptions!$C:$E,MATCH("Monthly oracle/data cost",Assumptions!$B:$B,0),MATCH(B2,Assumptions!$C$3:$E$3,0)) | L2: =INDEX(Assumptions!$C:$E,MATCH("Monthly infrastructure cost",Assumptions!$B:$B,0),MATCH(B2,Assumptions!$C$3:$E$3,0)) | M2: =INDEX(Assumptions!$C:$E,MATCH("Monthly audit/security reserve",Assumptions!$B:$B,0),MATCH(B2,Assumptions!$C$3:$E$3,0)) | N2: =INDEX(Assumptions!$C:$E,MATCH("Monthly jackpot top-up reserve",Assumptions!$B:$B,0),MATCH(B2,Assumptions!$C$3:$E$3,0)) | O2: =SUM(E2)
A3: 2 | B3: Conservative | C3: =SUMIFS(Funnel!$H:$H,Funnel!$A:$A,A3,Funnel!$B:$B,B3) | D3: =SUMIFS(Funnel!$J:$J,Funnel!$A:$A,A3,Funnel!$B:$B,B3) | E3: =C3*INDEX(Assumptions!$C:$E,MATCH("Partner share of first buyers",Assumptions!$B:$B,0),MATCH(B3,Assumptions!$C$3:$E$3,0))*INDEX(Assumptions!$C:$E,MATCH("CPA per qualified player",Assumptions!$B:$B,0),MATCH(B3,Assumptions!$C$3:$E$3,0))*INDEX(Assumptions!$C:$E,MATCH("CPA approved rate",Assumptions!$B:$B,0),MATCH(B3,Assumptions!$C$3:$E$3,0)) | F3: =INDEX(Assumptions!$C:$E,MATCH("Monthly marketing fixed budget",Assumptions!$B:$B,0),MATCH(B3,Assumptions!$C$3:$E$3,0)) | G3: =D3*INDEX(Assumptions!$C:$E,MATCH("KYC required rate",Assumptions!$B:$B,0),MATCH(B3,Assumptions!$C$3:$E$3,0))*INDEX(Assumptions!$C:$E,MATCH("KYC cost per checked user",Assumptions!$B:$B,0),MATCH(B3,Assumptions!$C$3:$E$3,0)) | H3: =D3*INDEX(Assumptions!$C:$E,MATCH("Support cost per active user",Assumptions!$B:$B,0),MATCH(B3,Assumptions!$C$3:$E$3,0)) | I3: =INDEX(Assumptions!$C:$E,MATCH("Monthly product/dev/ops cost",Assumptions!$B:$B,0),MATCH(B3,Assumptions!$C$3:$E$3,0)) | J3: =INDEX(Assumptions!$C:$E,MATCH("Monthly legal/compliance reserve",Assumptions!$B:$B,0),MATCH(B3,Assumptions!$C$3:$E$3,0)) | K3: =INDEX(Assumptions!$C:$E,MATCH("Monthly oracle/data cost",Assumptions!$B:$B,0),MATCH(B3,Assumptions!$C$3:$E$3,0)) | L3: =INDEX(Assumptions!$C:$E,MATCH("Monthly infrastructure cost",Assumptions!$B:$B,0),MATCH(B3,Assumptions!$C$3:$E$3,0)) | M3: =INDEX(Assumptions!$C:$E,MATCH("Monthly audit/security reserve",Assumptions!$B:$B,0),MATCH(B3,Assumptions!$C$3:$E$3,0)) | N3: =INDEX(Assumptions!$C:$E,MATCH("Monthly jackpot top-up reserve",Assumptions!$B:$B,0),MATCH(B3,Assumptions!$C$3:$E$3,0)) | O3: =SUM(E3)
